Workbook

Sheet LEVEL PREMIUM Model
A1: Level Premium Insurance Female age 40 Smoker Spring 2024
A2: Input Items: (rows 1-21) | E2: Section | F2: 1 | G2: Input Items
A3: Number of Policies Sold Fall 2024 | B3: 100000
A4: Average Face amount Per Policy | B4: ='Sensitivity Tests'!B1 -> 300000
A5: Earned Interest Rate | B5: ='Sensitivity Tests'!B46 -> 0.043 | C5: =B5 -> 0.043 | D5: =C5 -> 0.043 | E5: =D5 -> 0.043 | F5: =E5 -> 0.043 | G5: =F5 -> 0.043 | H5: =G5 -> 0.043 | I5: =H5 -> 0.043 | J5: =I5 -> 0.043 | K5: =J5 -> 0.043
A7: Expenses
A8: Acquisition Expense Per Policy | B8: ='Sensitivity Tests'!B6 -> 50
A9: Acquisition Expense Per $1000 face amount | B9: ='Sensitivity Tests'!B11 -> 0.25
A10: Maintenance Expense Per Policy Per year | B10: ='Sensitivity Tests'!B16 -> 10
A11: Maintenance Expense Per $1000 inforce | B11: ='Sensitivity Tests'!B21 -> 0.05
A12: Tax rate | B12: ='Sensitivity Tests'!B26 -> 0.21
A13: Year | B13: 1 | C13: 2 | D13: 3 | E13: 4 | F13: 5 | G13: 6 | H13: 7 | I13: 8 | J13: 9 | K13: 10
A14: Premium per $1000 | B14: 2.4 | C14: 2.4 | D14: 2.4 | E14: 2.4 | F14: 2.4 | G14: 2.4 | H14: 2.4 | I14: 2.4 | J14: 2.4 | K14: 2.4
A15: First year Lapse rate | B15: ='Sensitivity Tests'!B38 -> 0.2
A16: Renewal Years Lapse rates | C16: ='Sensitivity Tests'!B42 -> 0.1 | D16: =C16 -> 0.1 | E16: =D16 -> 0.1 | F16: =E16 -> 0.1 | G16: =F16 -> 0.1 | H16: =G16 -> 0.1 | I16: =H16 -> 0.1 | J16: =I16 -> 0.1 | K16: 1
A17: First year Comission rate | B17: 0.7
A18: Renewal Commission rate | C18: 0.05 | D18: =$C$18 -> 0.05 | E18: =$C$18 -> 0.05 | F18: =$C$18 -> 0.05 | G18: =$C$18 -> 0.05 | H18: =$C$18 -> 0.05 | I18: =$C$18 -> 0.05 | J18: =$C$18 -> 0.05 | K18: =$C$18 -> 0.05
A19: Age | B19: 40 | C19: =B19+1 -> 41 | D19: =C19+1 -> 42 | E19: =D19+1 -> 43 | F19: =E19+1 -> 44 | G19: =F19+1 -> 45 | H19: =G19+1 -> 46 | I19: =H19+1 -> 47 | J19: =I19+1 -> 48 | K19: =J19+1 -> 49
A20: Best Estimate mortality rate | B20: =$B$100*B101 -> 0.00079722 | C20: =$B$100*C101 -> 0.00098262 | D20: =$B$100*D101 -> 0.0012051 | E20: =$B$100*E101 -> 0.00146466 | F20: =$B$100*F101 -> 0.00175203 | G20: =$B$100*G101 -> 0.00208575 | H20: =$B$100*H101 -> 0.00245655 | I20: =$B$100*I101 -> 0.00286443 | ... K20: =$B$100*K101 -> 0.0038007
A21: Benchmark Surplus as % of expected one year claims | B21: 0.25
A22: Notes and assumptions:
A23: Timing of cash Flows: | B23: Premiums and acquisition expenses (incl commissions) are paid at the beginning of the year
B24: Death benefits and maintenance expenses occur uniformly throughout the year
E25: Section | F25: 2 | G25: Intermediate Calculations
A26: Beginning of Year | B26: 1 | C26: 2 | D26: 3 | E26: 4 | F26: 5 | G26: 6 | H26: 7 | I26: 8 | J26: 9 | K26: 10 | L26: 11
A27: Number of policies in force | B27: =B3 -> 100000 | C27: =B27*(1-B20)*(1-B15) -> 79936.222 | D27: =C27*(1-C20)*(1-C16) -> 71871.908 | E27: =D27*(1-D16)*(1-D20) -> 64606.766 | F27: =E27*(1-E20)*(1-E16) -> 58060.925 | G27: =F27*(1-F20)*(1-F16) -> 52163.28 | H27: =G27*(1-G20)*(1-G16) -> 46849.033 | I27: =H27*(1-H20)*(1-H16) -> 42060.551 | J27: =I27*(1-I20)*(1-I16) -> 37746.064 | K27: =J27*(1-J20)*(1-J16) -> 33858.718
A28: Face Amount in Force | B28: =B27*B4 -> 30000000000 | C28: =C27*B4 -> 23980866720 | D28: =D27*B4 -> 2.1561572e+10 | E28: =E27*B4 -> 1.938203e+10 | F28: =F27*B4 -> 1.7418277e+10 | G28: =G27*B4 -> 1.5648984e+10 | H28: =H27*B4 -> 1.405471e+10 | I28: =I27*B4 -> 1.2618165e+10 | J28: =J27*B4 -> 1.1323819e+10 | K28: =K27*B4 -> 1.0157615e+10
A30: Statutory Income Statement- Cash Flows | E30: Section | F30: 2.967772 | G30: Statutory Income
A31: Year | B31: 1 | C31: 2 | D31: 3 | E31: 4 | F31: 5 | G31: 6 | H31: 7 | I31: 8 | J31: 9 | K31: 10 | L31: 11
A32: Premiums | B32: =B27*(B4/1000)*B14 -> 72000000 | C32: =C27*(B4/1000)*C14 -> 57554080 | D32: =D27*(B4/1000)*D14 -> 51747774 | E32: =E27*(B4/1000)*E14 -> 46516871 | F32: =F27*(B4/1000)*F14 -> 41803866 | G32: =G27*(B4/1000)*G14 -> 37557562 | H32: =H27*(B4/1000)*H14 -> 33731303 | I32: =I27*(B4/1000)*I14 -> 30283597 | J32: =J27*(B4/1000)*J14 -> 27177166 | K32: =K27*(B4/1000)*K14 -> 24378277
A33: Net Investment Income | B33: =(B32-B38-B40)*B5-(B36+B39)*(B5/2) -> -176656.9 | C33: =((B87+C32-C40)*B5)-((C36+C39)*(B5/2)) -> 2436384.2 | D33: =((C87+D32-D40)*C5)-((D36+D39)*(C5/2)) -> 3207864.9 | E33: =((D87+E32-E40)*D5)-((E36+E39)*(D5/2)) -> 3611255.8 | F33: =((E87+F32-F40)*E5)-((F36+F39)*(E5/2)) -> 3700063.8 | G33: =((F87+G32-G40)*F5)-((G36+G39)*(F5/2)) -> 3521917.1 | H33: =((G87+H32-H40)*G5)-((H36+H39)*(G5/2)) -> 3118037.9 | I33: =((H87+I32-I40)*H5)-((I36+I39)*(H5/2)) -> 2530834.2 | J33: =((I87+J32-J40)*I5)-((J36+J39)*(I5/2)) -> 1796995 | K33: =((J87+K32-K40)*J5)-((K36+K39)*(J5/2)) -> 952150.48
A34: Sub-total-income | B34: =B32+B33 -> 71823343 | C34: =C32+C33 -> 59990464 | D34: =D32+D33 -> 54955639 | E34: =E32+E33 -> 50128127 | F34: =F32+F33 -> 45503930 | G34: =G32+G33 -> 41079479 | H34: =H32+H33 -> 36849341 | I34: =I32+I33 -> 32814431 | ... K34: =K32+K33 -> 25330428
A36: Death Benefits Paid | B36: =B28*B20 -> 23916600 | C36: =C28*C20 -> 23564079 | D36: =D28*D20 -> 25983851 | E36: =E28*E20 -> 28388084 | F36: =F28*F20 -> 30517345 | G36: =G28*G20 -> 32639869 | H36: =H28*H20 -> 34526097 | I36: =I28*I20 -> 36143851 | ... K36: =K28*K20 -> 38606049
A37: Expenses:
A38: Acquisition | B38: =(B3*B8)+(B28/1000)*B9 -> 12500000
A39: Maintenance | B39: =(B3*B10)+(B76/1000)*B11 -> 2500000 | C39: =(C27*B10)+(C28/1000)*B11 -> 1998405.6 | D39: =(D27*B10)+(D28/1000)*B11 -> 1796797.7 | E39: =(E27*B10)+(E28/1000)*B11 -> 1615169.1 | F39: =(F27*B10)+(F28/1000)*B11 -> 1451523.1 | G39: =(G27*B10)+(G28/1000)*B11 -> 1304082 | H39: =(H27*B10)+(H28/1000)*B11 -> 1171225.8 | I39: =(I27*B10)+(I28/1000)*B11 -> 1051513.8 | J39: =(J27*B10)+(J28/1000)*B11 -> 943651.61 | K39: =(K27*B10)+(K28/1000)*B11 -> 846467.96
A40: Commissions | B40: =B32*B17 -> 50400000 | C40: =C32*C18 -> 2877704 | D40: =D32*D18 -> 2587388.7 | E40: =E32*E18 -> 2325843.6 | F40: =F32*F18 -> 2090193.3 | G40: =G32*G18 -> 1877878.1 | H40: =H32*H18 -> 1686565.2 | I40: =I32*I18 -> 1514179.8 | J40: =J32*J18 -> 1358858.3 | K40: =K32*K18 -> 1218913.9
A41: Change in Reserve | B41: =B88 -> 14764965 | C41: =C88 -> 24566483 | D41: =D88 -> 15461843 | E41: =E88 -> 7525465 | F41: =F88 -> 878585.21 | G41: =G88 -> -4880907.5 | H41: =H88 -> -9631558.4 | I41: =I88 -> -13450824 | ... K41: =K88 -> -18709930
A42: Sub-total-benefits and expenses | B42: =B36+B38+B39+B40+B41 -> 1.0408156e+08 | C42: =C36+C38+C39+C40+C41 -> 53006672 | D42: =D36+D39+D40+D41 -> 45829880 | E42: =E36+E39+E40+E41 -> 39854561 | F42: =F36+F39+F40+F41 -> 34937646 | G42: =G36+G39+G40+G41 -> 30940921 | H42: =H36+H39+H40+H41 -> 27752330 | I42: =I36+I39+I40+I41 -> 25258721 | J42: =J36+J39+J40+J41 -> 23358294 | K42: =K36+K39+K40+K41 -> 21961501 | L42: 0
A44: Pre-tax income | B44: =B32+B33-B42 -> -32258221 | C44: =C32+C33-C42 -> 6983792.1 | D44: =D32+D33-D42 -> 9125758.4 | E44: =E32+E33-E42 -> 10273566 | F44: =F32+F33-F42 -> 10566283 | G44: =G32+G33-G42 -> 10138558 | H44: =H32+H33-H42 -> 9097011.6 | I44: =I32+I33-I42 -> 7555709.7 | ... K44: =K32+K33-K42 -> 3368926.3 | L44: 0
...

Sheet YRT Model
A1: Yearly Renewable Term Insurance Female age 40 Smoker Spring 2024
A2: Input Items: (rows 1-21) | E2: Section | F2: 1 | G2: Input Items
A3: Number of Policies Sold Fall 2024 | B3: 100000
A4: Average Face amount Per Policy | B4: ='Sensitivity Tests'!B1 -> 300000
A5: Earned Interest Rate | B5: ='Sensitivity Tests'!B46 -> 0.043 | C5: =B5 -> 0.043 | D5: =C5 -> 0.043 | E5: =D5 -> 0.043 | F5: =E5 -> 0.043 | G5: =F5 -> 0.043 | H5: =G5 -> 0.043 | I5: =H5 -> 0.043 | J5: =I5 -> 0.043 | K5: =J5 -> 0.043
A7: Expenses
A8: Acquisition Expense Per Policy | B8: ='Sensitivity Tests'!B6 -> 50
A9: Acquisition Expense Per $1000 face amount | B9: ='Sensitivity Tests'!B11 -> 0.25
A10: Maintenance Expense Per Policy Per year | B10: ='Sensitivity Tests'!B16 -> 10
A11: Maintenance Expense Per $1000 inforce | B11: ='Sensitivity Tests'!B21 -> 0.05
A12: Tax rate | B12: ='Sensitivity Tests'!B26 -> 0.21
A13: Year | B13: 1 | C13: 2 | D13: 3 | E13: 4 | F13: 5 | G13: 6 | H13: 7 | I13: 8 | J13: 9 | K13: 10
A14: Premium per $1000 | B14: 1.07 | C14: 1.33 | D14: 1.62 | E14: 1.95 | F14: 2.32 | G14: 2.76 | H14: 3.24 | I14: 3.76 | J14: 4.35 | K14: 4.97
A15: First year Lapse rate | B15: ='Sensitivity Tests'!B38 -> 0.2
A16: Renewal Years Lapse rates | C16: ='Sensitivity Tests'!B42 -> 0.1 | D16: =C16 -> 0.1 | E16: =D16 -> 0.1 | F16: =E16 -> 0.1 | G16: =F16 -> 0.1 | H16: =G16 -> 0.1 | I16: =H16 -> 0.1 | J16: =I16 -> 0.1 | K16: 1
A17: First year Comission rate | B17: 0.7
A18: Renewal Commission rate | C18: 0.05 | D18: =$C$18 -> 0.05 | E18: =$C$18 -> 0.05 | F18: =$C$18 -> 0.05 | G18: =$C$18 -> 0.05 | H18: =$C$18 -> 0.05 | I18: =$C$18 -> 0.05 | J18: =$C$18 -> 0.05 | K18: =$C$18 -> 0.05
A19: Age | B19: 40 | C19: =B19+1 -> 41 | D19: =C19+1 -> 42 | E19: =D19+1 -> 43 | F19: =E19+1 -> 44 | G19: =F19+1 -> 45 | H19: =G19+1 -> 46 | I19: =H19+1 -> 47 | J19: =I19+1 -> 48 | K19: =J19+1 -> 49
A20: Best Estimate mortality rate | B20: =$B$100*B101 -> 0.00079722 | C20: =$B$100*C101 -> 0.00098262 | D20: =$B$100*D101 -> 0.0012051 | E20: =$B$100*E101 -> 0.00146466 | F20: =$B$100*F101 -> 0.00175203 | G20: =$B$100*G101 -> 0.00208575 | H20: =$B$100*H101 -> 0.00245655 | I20: =$B$100*I101 -> 0.00286443 | ... K20: =$B$100*K101 -> 0.0038007
A21: Benchmark Surplus as % of expected one year claims | B21: 0.25
A22: Notes and assumptions:
A23: Timing of cash Flows: | B23: Premiums and acquisition expenses (incl commissions) are paid at the beginning of the year
B24: Death benefits and maintenance expenses occur uniformly throughout the year
E25: Section | F25: 2 | G25: Intermediate Calculations
A26: Beginning of Year | B26: 1 | C26: 2 | D26: 3 | E26: 4 | F26: 5 | G26: 6 | H26: 7 | I26: 8 | J26: 9 | K26: 10 | L26: 11
A27: Number of policies in force | B27: =B3 -> 100000 | C27: =B27*(1-B20)*(1-B15) -> 79936.222 | D27: =C27*(1-C20)*(1-C16) -> 71871.908 | E27: =D27*(1-D16)*(1-D20) -> 64606.766 | F27: =E27*(1-E20)*(1-E16) -> 58060.925 | G27: =F27*(1-F20)*(1-F16) -> 52163.28 | H27: =G27*(1-G20)*(1-G16) -> 46849.033 | I27: =H27*(1-H20)*(1-H16) -> 42060.551 | J27: =I27*(1-I20)*(1-I16) -> 37746.064 | K27: =J27*(1-J20)*(1-J16) -> 33858.718
A28: Face Amount in Force | B28: =B27*B4 -> 30000000000 | C28: =C27*B4 -> 23980866720 | D28: =D27*B4 -> 2.1561572e+10 | E28: =E27*B4 -> 1.938203e+10 | F28: =F27*B4 -> 1.7418277e+10 | G28: =G27*B4 -> 1.5648984e+10 | H28: =H27*B4 -> 1.405471e+10 | I28: =I27*B4 -> 1.2618165e+10 | J28: =J27*B4 -> 1.1323819e+10 | K28: =K27*B4 -> 1.0157615e+10
A30: Statutory Income Statement- Cash Flows | E30: Section | F30: 2.967772 | G30: Statutory Income
A31: Year | B31: 1 | C31: 2 | D31: 3 | E31: 4 | F31: 5 | G31: 6 | H31: 7 | I31: 8 | J31: 9 | K31: 10 | L31: 11
A32: Premiums | B32: =B27*(B4/1000)*B14 -> 32100000 | C32: =C27*(B4/1000)*C14 -> 31894553 | D32: =D27*(B4/1000)*D14 -> 34929747 | E32: =E27*(B4/1000)*E14 -> 37794958 | F32: =F27*(B4/1000)*F14 -> 40410404 | G32: =G27*(B4/1000)*G14 -> 43191196 | H32: =H27*(B4/1000)*H14 -> 45537260 | I32: =I27*(B4/1000)*I14 -> 47444302 | J32: =J27*(B4/1000)*J14 -> 49258614 | K32: =K27*(B4/1000)*K14 -> 50483349
A33: Net Investment Income | B33: =(B32-B38-B40)*B5-(B36+B39)*(B5/2) -> -691366.9 | C33: =((B87+C32-C40)*B5)-((C36+C39)*(B5/2)) -> 753299.06 | D33: =((C87+D32-D40)*C5)-((D36+D39)*(C5/2)) -> 829596.23 | E33: =((D87+E32-E40)*D5)-((E36+E39)*(D5/2)) -> 898854.1 | F33: =((E87+F32-F40)*E5)-((F36+F39)*(E5/2)) -> 963434.33 | G33: =((F87+G32-G40)*F5)-((G36+G39)*(F5/2)) -> 1034565.4 | H33: =((G87+H32-H40)*G5)-((H36+H39)*(G5/2)) -> 1092704.6 | I33: =((H87+I32-I40)*H5)-((I36+I39)*(H5/2)) -> 1138399.4 | J33: =((I87+J32-J40)*I5)-((J36+J39)*(I5/2)) -> 1183957.9 | K33: =((J87+K32-K40)*J5)-((K36+K39)*(J5/2)) -> 1214015.7
A34: Sub-total-income | B34: =B32+B33 -> 31408633 | C34: =C32+C33 -> 32647852 | D34: =D32+D33 -> 35759343 | E34: =E32+E33 -> 38693812 | F34: =F32+F33 -> 41373838 | G34: =G32+G33 -> 44225761 | H34: =H32+H33 -> 46629964 | I34: =I32+I33 -> 48582701 | ... K34: =K32+K33 -> 51697365
A36: Death Benefits Paid | B36: =B28*B20 -> 23916600 | C36: =C28*C20 -> 23564079 | D36: =D28*D20 -> 25983851 | E36: =E28*E20 -> 28388084 | F36: =F28*F20 -> 30517345 | G36: =G28*G20 -> 32639869 | H36: =H28*H20 -> 34526097 | I36: =I28*I20 -> 36143851 | ... K36: =K28*K20 -> 38606049
A37: Expenses:
A38: Acquisition | B38: =(B3*B8)+(B28/1000)*B9 -> 12500000
A39: Maintenance | B39: =(B3*B10)+(B76/1000)*B11 -> 2500000 | C39: =(C27*B10)+(C28/1000)*B11 -> 1998405.6 | D39: =(D27*B10)+(D28/1000)*B11 -> 1796797.7 | E39: =(E27*B10)+(E28/1000)*B11 -> 1615169.1 | F39: =(F27*B10)+(F28/1000)*B11 -> 1451523.1 | G39: =(G27*B10)+(G28/1000)*B11 -> 1304082 | H39: =(H27*B10)+(H28/1000)*B11 -> 1171225.8 | I39: =(I27*B10)+(I28/1000)*B11 -> 1051513.8 | J39: =(J27*B10)+(J28/1000)*B11 -> 943651.61 | K39: =(K27*B10)+(K28/1000)*B11 -> 846467.96
A40: Commissions | B40: =B32*B17 -> 22470000 | C40: =C32*C18 -> 1594727.6 | D40: =D32*D18 -> 1746487.4 | E40: =E32*E18 -> 1889747.9 | F40: =F32*F18 -> 2020520.2 | G40: =G32*G18 -> 2159559.8 | H40: =H32*H18 -> 2276863 | I40: =I32*I18 -> 2372215.1 | J40: =J32*J18 -> 2462930.7 | K40: =K32*K18 -> 2524167.4
A41: Change in Reserve | B41: =B88 -> 0 | C41: =C88 -> 0 | D41: =D88 -> 0 | E41: =E88 -> 0 | F41: =F88 -> 0 | G41: =G88 -> 0 | H41: =H88 -> 0 | I41: =I88 -> 0 | ... K41: =K88 -> 0
A42: Sub-total-benefits and expenses | B42: =B36+B38+B39+B40+B41 -> 61386600 | C42: =C36+C38+C39+C40+C41 -> 27157212 | D42: =D36+D39+D40+D41 -> 29527136 | E42: =E36+E39+E40+E41 -> 31893001 | F42: =F36+F39+F40+F41 -> 33989388 | G42: =G36+G39+G40+G41 -> 36103510 | H42: =H36+H39+H40+H41 -> 37974186 | I42: =I36+I39+I40+I41 -> 39567580 | J42: =J36+J39+J40+J41 -> 40986489 | K42: =K36+K39+K40+K41 -> 41976685 | L42: 0
A44: Pre-tax income | B44: =B32+B33-B42 -> -29977967 | C44: =C32+C33-C42 -> 5490639.3 | D44: =D32+D33-D42 -> 6232207.5 | E44: =E32+E33-E42 -> 6800811.3 | F44: =F32+F33-F42 -> 7384450.1 | G44: =G32+G33-G42 -> 8122251.1 | H44: =H32+H33-H42 -> 8655778.2 | I44: =I32+I33-I42 -> 9015120.8 | ... K44: =K32+K33-K42 -> 9720680.1 | L44: 0
...

Sheet Sensitivity Tests
A1: Average Face Amount Per Policy | B1: 300000 | C1: 100000 | D1: =C1+20000 -> 120000 | E1: =D1+20000 -> 140000 | F1: =E1+20000 -> 160000 | G1: =F1+20000 -> 180000 | H1: =G1+20000 -> 200000 | I1: =H1+20000 -> 220000 | J1: =I1+20000 -> 240000 | K1: =J1+20000 -> 260000 | ... U1: =T1+20000 -> 460000
A2: Level Premium | B2: ='LEVEL PREMIUM Model'!B56 -> 0.1699142 | C2: 0.06435708 | D2: 0.08411908 | E2: 0.1003098 | F2: 0.113859 | G2: 0.12538752 | H2: 0.13532962 | I2: 0.14400002 | J2: 0.1516334 | K2: 0.15840885 | L2: 0.1644657 | M2: 0.1699142 | N2: 0.1748428 | O2: 0.17932341 | P2: 0.18341508 | Q2: 0.18716682 | R2: 0.19061968 | S2: 0.19380828 | T2: 0.19676206 | U2: 0.1995062
A3: YRT | B3: ='YRT Model'!B56 -> 0.15057227 | C3: 0.06058427 | D3: 0.079637301 | E3: 0.094438523 | F3: 0.10629178 | G3: 0.11600968 | H3: 0.12412783 | I3: 0.13101478 | J3: 0.136933 | K3: 0.1420748 | L3: 0.14658442 | M3: 0.15057227 | N3: 0.15412434 | O3: 0.15730865 | P3: 0.16017968 | Q3: 0.16278166 | R3: 0.1651508 | S3: 0.16731711 | T3: 0.16930562 | U3: 0.17113741
A6: Acquisition Expense Per Policy | B6: 50 | C6: 45 | D6: =C6+1 -> 46 | E6: =D6+1 -> 47 | F6: =E6+1 -> 48 | G6: =F6+1 -> 49 | H6: =G6+1 -> 50 | I6: =H6+1 -> 51 | J6: =I6+1 -> 52 | K6: =J6+1 -> 53 | ... M6: =L6+1 -> 55
A7: Level Premium | B7: ='LEVEL PREMIUM Model'!B56 -> 0.1699142 | C7: 0.17364445 | D7: 0.17289194 | E7: 0.17214269 | F7: 0.17139666 | G7: 0.17065384 | H7: 0.1699142 | I7: 0.16917771 | J7: 0.16844437 | K7: 0.16771413 | L7: 0.16698699 | M7: 0.16626291
A8: YRT | B8: ='YRT Model'!B56 -> 0.15057227 | C8: 0.15382724 | D8: 0.15317062 | E8: 0.15251683 | F8: 0.15186585 | G8: 0.15121767 | H8: 0.15057227 | I8: 0.14992961 | J8: 0.14928969 | K8: 0.14865248 | L8: 0.14801796 | M8: 0.14738611
A11: Acquisition Expense Per $1000 face amount | B11: 0.25 | C11: 0.1 | D11: =C11+0.05 -> 0.15 | E11: =D11+0.05 -> 0.2 | F11: =E11+0.05 -> 0.25 | G11: =F11+0.05 -> 0.3 | H11: =G11+0.05 -> 0.35 | I11: =H11+0.05 -> 0.4 | J11: =I11+0.05 -> 0.45 | K11: =J11+0.05 -> 0.5 | ... M11: =L11+0.05 -> 0.6
A12: Level Premium | B12: =B7 -> 0.1699142 | C12: 0.2067179 | D12: 0.19358889 | E12: 0.18135378 | F12: 0.1699142 | G12: 0.15918617 | H12: 0.14909757 | I12: 0.13958605 | J12: 0.13059743 | K12: 0.12208435 | L12: 0.11400524 | M12: 0.10632344
A13: YRT | B13: =B8 -> 0.15057227 | C13: 0.18269696 | D13: 0.17123274 | E13: 0.16055443 | F13: 0.15057227 | G13: 0.14121032 | H13: 0.13240385 | I13: 0.12409728 | J13: 0.11624262 | K13: 0.10879813 | L13: 0.10172734 | M13: 0.094998234
A16: Maintenance Expense Per Policy Per year | B16: 10 | C16: 5 | D16: =C16+1 -> 6 | E16: =D16+1 -> 7 | F16: =E16+1 -> 8 | G16: =F16+1 -> 9 | H16: =G16+1 -> 10 | I16: =H16+1 -> 11 | J16: =I16+1 -> 12 | K16: =J16+1 -> 13 | ... M16: =L16+1 -> 15
A17: Level Premium | B17: =B12 -> 0.1699142 | C17: 0.19184619 | D17: 0.18719142 | E17: 0.18267772 | F17: 0.17829796 | G17: 0.17404552 | H17: 0.1699142 | I17: 0.16589824 | J17: 0.16199225 | K17: 0.1581912 | L17: 0.15449036 | M17: 0.1508853
A18: YRT | B18: =B13 -> 0.15057227 | C18: 0.16281258 | D18: 0.16033838 | E18: 0.15787738 | F18: 0.15542945 | G18: 0.15299445 | H18: 0.15057227 | I18: 0.14816277 | J18: 0.14576583 | K18: 0.14338133 | L18: 0.14100916 | M18: 0.13864918
A21: Maintenance Expense Per $1000 inforce | B21: 0.05 | C21: 0.01 | D21: =C21+0.01 -> 0.02 | E21: =D21+0.01 -> 0.03 | F21: =E21+0.01 -> 0.04 | G21: =F21+0.01 -> 0.05 | H21: =G21+0.01 -> 0.06 | I21: =H21+0.01 -> 0.07 | J21: =I21+0.01 -> 0.08 | K21: =J21+0.01 -> 0.09 | ... M21: =L21+0.01 -> 0.11
A22: Level Premium | B22: =B12 -> 0.1699142 | C22: 0.2291075 | D22: 0.21203868 | E22: 0.19664969 | F22: 0.18267772 | G22: 0.1699142 | H22: 0.1581912 | I22: 0.14737186 | J22: 0.13734333 | K22: 0.12801162 | L22: 0.11929776 | M22: 0.11113482
A23: YRT | B23: =B18 -> 0.15057227 | C23: 0.18051273 | D23: 0.172844 | E23: 0.16530011 | F23: 0.15787738 | G23: 0.15057227 | H23: 0.14338133 | I23: 0.13630127 | J23: 0.12932889 | K23: 0.12246108 | L23: 0.11569487 | M23: 0.10902737
A26: Tax Rate | B26: =21% -> 0.21 | C26: =0.15 -> 0.15 | D26: =C26+0.01 -> 0.16 | E26: =D26+0.01 -> 0.17 | F26: =E26+0.01 -> 0.18 | G26: =F26+0.01 -> 0.19 | H26: =G26+0.01 -> 0.2 | I26: =H26+0.01 -> 0.21 | J26: =I26+0.01 -> 0.22 | K26: =J26+0.01 -> 0.23 | ... M26: =L26+0.01 -> 0.25
A27: Level Premium | B27: =B22 -> 0.1699142 | C27: 0.17359489 | D27: 0.17300953 | E27: 0.17241334 | F27: 0.17180603 | G27: 0.17118728 | H27: 0.17055678 | I27: 0.1699142 | J27: 0.16925918 | K27: 0.16859139 | L27: 0.16791044 | M27: 0.16721595
A28: YRT | B28: =B23 -> 0.15057227 | C28: 0.15365557 | D28: 0.15316511 | E28: 0.15266562 | F28: 0.15215685 | G28: 0.15163855 | H28: 0.15111045 | I28: 0.15057227 | J28: 0.15002372 | K28: 0.14946451 | L28: 0.14889432 | M28: 0.14831284
A30: Mortality Factor | B30: 1 | C30: 0.7 | D30: =C30+0.01 -> 0.71 | E30: =D30+0.01 -> 0.72 | F30: =E30+0.01 -> 0.73 | G30: =F30+0.01 -> 0.74 | H30: =G30+0.01 -> 0.75 | I30: =H30+0.01 -> 0.76 | J30: =I30+0.01 -> 0.77 | K30: =J30+0.01 -> 0.78 | ... BH30: =BG30+0.01 -> 1.27
A31: Level Premium | B31: ='LEVEL PREMIUM Model'!B56 -> 0.1699142 | C31: 0.55124488 | D31: 0.53652779 | E31: 0.52202733 | F31: 0.5077339 | G31: 0.49363818 | H31: 0.47973113 | I31: 0.46600391 | J31: 0.4524479 | K31: 0.43905471 | L31: 0.42581609 | M31: 0.41272398 | N31: 0.39977044 | O31: 0.38694767 | P31: 0.37424798 | Q31: 0.36166377 | R31: 0.34918752 | S31: 0.33681177 | T31: 0.3245291 | U31: 0.3123321 | V31: 0.30021341 | W31: 0.2881656 | X31: 0.27618127 | Y31: 0.26425293 | Z31: 0.25237304 | AA31: 0.24053399 | AB31: 0.22872803 | AC31: 0.21694732 | AD31: 0.20518385 | AE31: 0.19342944 | AF31: 0.18167575 | AG31: 0.1699142 | AH31: 0.158136 | AI31: 0.14633211 | AJ31: 0.13449323 | AK31: 0.12260979 | AL31: 0.11067195 | AM31: 0.098669587 | AN31: 0.086592304 | AO31: 0.074429484 | AP31: 0.062170314 | AQ31: 0.049803865 | AR31: 0.037319193 | AS31: 0.024705491 | AT31: 0.011952292 | AU31: -0.0009502575 | AV31: -0.014011037 | AW31: -0.027237494 | AX31: -0.040635063 | AY31: -0.05420646 | AZ31: -0.067950847 | BA31: -0.081862875 | BB31: -0.095931663 | BC31: -0.11013978 | BD31: -0.12446234 | BE31: -0.13886641 | BF31: -0.15331087 | BG31: -0.16774693 | BH31: -0.18211946
A32: YRT | B32: ='YRT Model'!B56 -> 0.15057227 | C32: 0.52692967 | D32: 0.51177318 | E32: 0.49688148 | F32: 0.4822433 | G32: 0.46784783 | H32: 0.45368463 | I32: 0.43974365 | J32: 0.4260152 | K32: 0.41248992 | L32: 0.39915877 | M32: 0.38601301 | N32: 0.37304417 | O32: 0.36024406 | P32: 0.34760471 | Q32: 0.33511841 | R32: 0.32277766 | S32: 0.31057516 | T32: 0.29850381 | U32: 0.28655669 | V32: 0.27472705 | W32: 0.26300831 | X32: 0.25139404 | Y32: 0.23987795 | Z32: 0.22845389 | AA32: 0.21711584 | AB32: 0.20585791 | AC32: 0.19467434 | AD32: 0.18355946 | AE32: 0.17250775 | AF32: 0.16151378 | AG32: 0.15057227 | AH32: 0.13967801 | AI32: 0.12882598 | AJ32: 0.11801123 | AK32: 0.107229 | AL32: 0.096474667 | AM32: 0.085743775 | AN32: 0.075032065 | AO32: 0.064335492 | AP32: 0.053650251 | AQ32: 0.04297281 | AR32: 0.032299948 | AS32: 0.021628795 | AT32: 0.01095688 | AU32: 0.00028218423 | AV32: -0.010396801 | AW32: -0.021081012 | AX32: -0.031770748 | AY32: -0.042465602 | AZ32: -0.053164386 | BA32: -0.06386507 | BB32: -0.074564714 | BC32: -0.085259409 | BD32: -0.095944235 | BE32: -0.10661323 | BF32: -0.11725938 | BG32: -0.12787464 | BH32: -0.13844997
A34: Mortality Factor | B34: =1 -> 1
A35: Level Premium | B35: ='LEVEL PREMIUM Model'!B56 -> 0.1699142
A36: YRT | B36: ='YRT Model'!B56 -> 0.15057227
A38: First Year Lapse Rate | B38: =20% -> 0.2 | C38: 0.15 | D38: =C38+0.01 -> 0.16 | E38: =D38+0.01 -> 0.17 | F38: =E38+0.01 -> 0.18 | G38: =F38+0.01 -> 0.19 | H38: =G38+0.01 -> 0.2 | I38: =H38+0.01 -> 0.21 | J38: =I38+0.01 -> 0.22 | K38: =J38+0.01 -> 0.23 | ... P38: =O38+0.01 -> 0.28
A39: Level Premium | B39: ='LEVEL PREMIUM Model'!B56 -> 0.1699142 | C39: 0.17773827 | D39: 0.17621767 | E39: 0.17467548 | F39: 0.17311118 | G39: 0.17152427 | H39: 0.1699142 | I39: 0.16828041 | J39: 0.16662234 | K39: 0.1649394 | L39: 0.16323095 | M39: 0.16149638 | N39: 0.159735 | O39: 0.15794615 | P39: 0.15612911
A40: YRT | B40: ='YRT Model'!B56 -> 0.15057227 | C40: 0.16218467 | D40: 0.15989947 | E40: 0.15759603 | F40: 0.15527395 | G40: 0.15293284 | H40: 0.15057227 | I40: 0.14819181 | J40: 0.14579103 | K40: 0.14336946 | L40: 0.14092662 | M40: 0.13846202 | N40: 0.13597513 | O40: 0.13346544 | P40: 0.13093238
A42: Renewal Lapse Rates | B42: =10% -> 0.1 | C42: 0.05 | D42: =C42+0.01 -> 0.06 | E42: =D42+0.01 -> 0.07 | F42: =E42+0.01 -> 0.08 | G42: =F42+0.01 -> 0.09 | H42: =G42+0.01 -> 0.1 | I42: =H42+0.01 -> 0.11 | J42: =I42+0.01 -> 0.12 | K42: =J42+0.01 -> 0.13 | ... P42: =O42+0.01 -> 0.18
A43: Level Premium | B43: ='LEVEL PREMIUM Model'!B56 -> 0.1699142 | C43: 0.1189249 | D43: 0.12974711 | E43: 0.14027012 | F43: 0.15047843 | G43: 0.16036176 | H43: 0.1699142 | I43: 0.17913356 | J43: 0.18802065 | K43: 0.19657865 | L43: 0.20481262 | M43: 0.21272899 | N43: 0.22033526 | O43: 0.22763961 | P43: 0.23465073
A44: YRT | B44: ='YRT Model'!B56 -> 0.15057227 | C44: 0.18800541 | D44: 0.18053765 | E44: 0.17306033 | F44: 0.16557356 | G44: 0.15807749 | H44: 0.15057227 | I44: 0.14305803 | J44: 0.13553497 | K44: 0.12800324 | L44: 0.12046305 | M44: 0.1129146 | N44: 0.1053581 | O44: 0.097793795 | P44: 0.090221925
A46: Earned Interest Rate | B46: =4.3% -> 0.043 | C46: =0.02 -> 0.02 | D46: =C46+0.001 -> 0.021 | E46: =D46+0.001 -> 0.022 | F46: =E46+0.001 -> 0.023 | G46: =F46+0.001 -> 0.024 | H46: =G46+0.001 -> 0.025 | I46: =H46+0.001 -> 0.026 | J46: =I46+0.001 -> 0.027 | K46: =J46+0.001 -> 0.028 | ... AD46: =AC46+0.001 -> 0.047
A47: Level Premium | B47: ='LEVEL PREMIUM Model'!B56 -> 0.1699142 | C47: 0.113671 | D47: 0.11616022 | E47: 0.11864543 | F47: 0.12112663 | G47: 0.12360382 | H47: 0.12607699 | I47: 0.12854615 | J47: 0.13101131 | K47: 0.13347246 | L47: 0.13592961 | M47: 0.13838277 | N47: 0.14083194 | O47: 0.14327713 | P47: 0.14571835 | Q47: 0.1481556 | R47: 0.1505889 | S47: 0.15301826 | T47: 0.15544368 | U47: 0.15786517 | V47: 0.16028275 | W47: 0.16269643 | X47: 0.16510622 | Y47: 0.16751214 | Z47: 0.1699142 | AA47: 0.1723124 | AB47: 0.17470678 | AC47: 0.17709733 | AD47: 0.17948409
A48: YRT | B48: ='YRT Model'!B56 -> 0.15057227 | C48: 0.13151609 | D48: 0.13235815 | E48: 0.13319895 | F48: 0.13403849 | G48: 0.13487677 | H48: 0.13571381 | I48: 0.1365496 | J48: 0.13738416 | K48: 0.13821748 | L48: 0.13904957 | M48: 0.13988044 | N48: 0.14071009 | O48: 0.14153852 | P48: 0.14236574 | Q48: 0.14319175 | R48: 0.14401656 | S48: 0.14484017 | T48: 0.14566258 | U48: 0.14648381 | V48: 0.14730386 | W48: 0.14812272 | X48: 0.1489404 | Y48: 0.14975692 | Z48: 0.15057227 | AA48: 0.15138645 | AB48: 0.15219947 | AC48: 0.15301134 | AD48: 0.15382206
A51: Level Premium Scenario | D51: Mortality Factors
A52: Earned Interest Rate | B52: ='LEVEL PREMIUM Model'!B56 -> 0.1699142 | C52: 0.8 | D52: =C52+0.02 -> 0.82 | E52: =D52+0.02 -> 0.84 | F52: =E52+0.02 -> 0.86 | G52: =F52+0.02 -> 0.88 | H52: =G52+0.02 -> 0.9 | I52: =H52+0.02 -> 0.92 | J52: =I52+0.02 -> 0.94 | K52: =J52+0.02 -> 0.96 | ... W52: =V52+0.02 -> 1.2
B53: =3% -> 0.03 | C53: 0.38077442 | D53: 0.35526746 | E53: 0.33020602 | F53: 0.30552885 | G53: 0.28117529 | H53: 0.2570847 | I53: 0.23319589 | J53: 0.20944656 | K53: 0.18577265 | L53: 0.16210778 | M53: 0.13838277 | N53: 0.11452516 | O53: 0.090459124 | P53: 0.066105784 | Q53: 0.04138444 | R53: 0.016215254 | S53: -0.0094756543 | T53: -0.035747431 | U53: -0.062630559 | V53: -0.09010678 | W53: -0.11808399
B54: =B53+0.002 -> 0.032 | C54: 0.38570785 | D54: 0.36016134 | E54: 0.33506768 | F54: 0.31036575 | G54: 0.28599506 | H54: 0.26189523 | I54: 0.23800536 | J54: 0.21426347 | K54: 0.1906059 | L54: 0.16696672 | M54: 0.14327713 | N54: 0.11946507 | O54: 0.09545493 | P54: 0.071167767 | Q54: 0.046522281 | R54: 0.02143712 | S54: -0.0041645904 | T54: -0.030347258 | U54: -0.057149848 | V54: -0.084566665 | W54: -0.11252235
B55: =B54+0.002 -> 0.034 | C55: 0.39063459 | D55: 0.36504783 | E55: 0.33992121 | F55: 0.31519374 | G55: 0.2908051 | H55: 0.26669513 | I55: 0.24280323 | J55: 0.21906777 | K55: 0.1954255 | L55: 0.17181089 | M55: 0.1481556 | N55: 0.12438799 | O55: 0.10043271 | P55: 0.076210889 | Q55: 0.051640776 | R55: 0.026639763 | S55: 0.0011283571 | T55: -0.024962587 | U55: -0.051679851 | V55: -0.079029597 | W55: -0.10695271
B56: =B55+0.002 -> 0.036 | C56: 0.39555471 | D56: 0.36992701 | E56: 0.34476671 | F56: 0.3200129 | G56: 0.29560547 | H56: 0.27148448 | I56: 0.24758961 | J56: 0.22385958 | K56: 0.20023153 | L56: 0.17664038 | M56: 0.15301826 | N56: 0.12929394 | O56: 0.10539246 | P56: 0.081235054 | Q56: 0.056739702 | R56: 0.031822768 | S56: 0.0064024946 | T56: -0.019594499 | U56: -0.046222158 | V56: -0.073497762 | W56: -0.10137787
B57: =B56+0.002 -> 0.038 | C57: 0.40046828 | D57: 0.37479896 | E57: 0.34960424 | F57: 0.32482334 | G57: 0.30039629 | H57: 0.27626339 | I57: 0.2523646 | J57: 0.22863899 | K57: 0.20502409 | L57: 0.18145529 | M57: 0.15786517 | N57: 0.13418299 | O57: 0.11033418 | P57: 0.086240193 | Q57: 0.061818872 | R57: 0.036985773 | S57: 0.011657201 | T57: -0.014243983 | U57: -0.040778247 | V57: -0.067973235 | W57: -0.095800503
...
